
using device cuda
Traceback (most recent call last):
  File "z:/prog/swevoice/train_2.py", line 131, in <module>
    main()
  File "z:/prog/swevoice/train_2.py", line 68, in main
    X_demo, Y_demo, _, _ = next(iter(val_loader))
  File "C:\Users\cerik\AppData\Local\Programs\Python\Python38\lib\site-packages\torch\utils\data\dataloader.py", line 530, in __next__
    data = self._next_data()
  File "C:\Users\cerik\AppData\Local\Programs\Python\Python38\lib\site-packages\torch\utils\data\dataloader.py", line 1224, in _next_data
    return self._process_data(data)
  File "C:\Users\cerik\AppData\Local\Programs\Python\Python38\lib\site-packages\torch\utils\data\dataloader.py", line 1250, in _process_data
    data.reraise()
  File "C:\Users\cerik\AppData\Local\Programs\Python\Python38\lib\site-packages\torch\_utils.py", line 457, in reraise
    raise exception
TypeError: Caught TypeError in DataLoader worker process 0.
Original Traceback (most recent call last):
  File "C:\Users\cerik\AppData\Local\Programs\Python\Python38\lib\site-packages\torch\utils\data\_utils\worker.py", line 287, in _worker_loop
    data = fetcher.fetch(index)
  File "C:\Users\cerik\AppData\Local\Programs\Python\Python38\lib\site-packages\torch\utils\data\_utils\fetch.py", line 49, in fetch
    data = [self.dataset[idx] for idx in possibly_batched_index]
  File "C:\Users\cerik\AppData\Local\Programs\Python\Python38\lib\site-packages\torch\utils\data\_utils\fetch.py", line 49, in <listcomp>
    data = [self.dataset[idx] for idx in possibly_batched_index]
  File "C:\Users\cerik\AppData\Local\Programs\Python\Python38\lib\site-packages\torch\utils\data\dataset.py", line 471, in __getitem__
    return self.dataset[self.indices[idx]]
  File "z:\prog\swevoice\dataset.py", line 88, in __getitem__
    spectrogram: torch.Tensor = torchaudio.transforms.MelSpectrogram(
TypeError: __init__() got an unexpected keyword argument 'device'